
<mujocoinclude >

    <body name="object">
      <body name="frame_left" pos="0 0 0.8" quat="0.707388 0 0 -0.706825">
          <inertial pos="0.3 0 0" quat="0.5 0.5 0.5 0.5" mass="7.85398" diaginertia="0.923301 0.764585 0.168533" />
          <geom size="0.03 0.799" pos="-0.05 0 0" type="cylinder" rgba="1 1 1 1" group="1" name="r_frame"/>
      </body>
      <!-- <body name="frame_right" pos="0 0 0.8" quat="0.707388 0 0 -0.706825"> -->
      <body name="frame_right" pos="0 0 0.8" quat="1 0 0 0">
          <inertial pos="0.3 0 0" quat="0.5 0.5 0.5 0.5" mass="7.85398" diaginertia="0.923301 0.764585 0.168533" />
          <geom size="0.03 0.799" pos="0 -0.83 0" type="cylinder" rgba="1 1 1 1" group="1" name="l_frame"/>
          <!-- <joint name="hinge" pos="0 -0.83 0" axis="0 0 1" range=".0 2.0" frictionloss="1" damping="0" springref="0" stiffness="1"/> -->
          <joint name="hinge" pos="0 -0.83 0" axis="0 0 1" range=".0 2.0" frictionloss="1" damping="1" springref="0" stiffness="1"/>
          <body name="hinge_axis" pos="0 -0.83 0" quat="1 0 0 0 ">
            <geom size="0.02" pos="0. 0. 0." quat="1 0 0 0" type="sphere" contype="0" conaffinity="0" rgba="1 1 1 1" />
          </body>
          <body name="door_body" pos="0 -0.4 0">
              <inertial pos="0.0296816 -0.00152345 0" quat="0.701072 0 0 0.713091" mass="2.43455" diaginertia="0.0913751 0.0521615 0.043714" />
              <geom size="0.02 0.4 0.75" type="box" friction="1 1 1" group="1" name="panel" material="MatDarkWood"/>
              <!-- <body name="latch" pos="0 0.3 0" quat="0.707388 0 0 -0.706825"> -->
              <body name="latch" pos="0 0.3 0.2" quat="0.707388 0 0 -0.706825">
              
              
                    <inertial pos="-0.017762 0.0138544 0" quat="0.365653 0.605347 -0.36522 0.605365" mass="3.53743" diaginertia="0.0483771 0.0410001 0.0111013" />
                    <joint name="latch" pos="0 0 0" axis="0 1 0" range="0 1.8" frictionloss="0" damping="0.0" springref="0" stiffness="0" />
                    <!-- <joint name="latch" pos="0 0 0" axis="0 1 0" range="0 1.8" frictionloss="0" damping="0.5" springref="0" stiffness="1" /> -->
                    
                    <geom name="latch_connector" size="0.05 0.15" quat="0.707388 0.706825 0 0" type="cylinder"/>
                    <geom name="door_handle" size="0.02 0.1" pos="0.1 -0.15 0" quat="0.707388 0 0.706825 0" type="capsule"  />
                    <geom name="latch_rear" size="0.04 0.07" pos="-0.1 0.1 0" quat="0.707388 0 0.706825 0" type="capsule"  />
                    <body name="latch_axis" pos="0 -0.15 0" quat="0.7071 0.7071 0 0">
                        <geom size="0.01" pos="0. 0. 0." quat="1 0 0 0" type="sphere" contype="0" conaffinity="0" rgba="1 1 1 1" />
                    </body>
            </body>
          </body>
      </body>

      <!-- <body name="frame_right" pos="0 0 0.8" quat="1 0 0 0">
          <inertial pos="0.3 0 0" quat="0.5 0.5 0.5 0.5" mass="7.85398" diaginertia="0.923301 0.764585 0.168533" />
          <geom size="0.03 0.8" pos="0.83 0 0" type="cylinder" rgba="1 1 1 1" group="1" name="l_frame"/>
          <joint name="hinge" pos="0.83 0 0" axis="0 0 1" range=".0 2.0" frictionloss="1" damping="0" springref="0" stiffness="1"/>
          <body name="hinge_axis" pos="0.83 0 0" quat="1 0 0 0 ">
            <geom size="0.02" pos="0. 0. 0." quat="1 0 0 0" type="sphere" contype="0" conaffinity="0" rgba="1 1 1 1" />
          </body>
          <body name="door_body" pos="0.4 0 0">
              <inertial pos="0.0296816 -0.00152345 0" quat="0.701072 0 0 0.713091" mass="2.43455" diaginertia="0.0913751 0.0521615 0.043714" />
              <geom size="0.4 0.02 0.75" type="box" friction="1 1 1" group="1" name="panel" material="MatDarkWood"/>
              <body name="latch" pos="-0.3 0 0">
                    <inertial pos="-0.017762 0.0138544 0" quat="0.365653 0.605347 -0.36522 0.605365" mass="3.53743" diaginertia="0.0483771 0.0410001 0.0111013" />
                    <joint name="latch" pos="0 0 0" axis="0 1 0" range="0 1.8" frictionloss="0.1" damping="0.5" springref="0" stiffness="1" />
                    
                    <geom size="0.05 0.15" quat="0.707388 0.706825 0 0" type="cylinder"/>
                    <geom size="0.02 0.1" pos="0.1 -0.15 0" quat="0.707388 0 0.706825 0" type="capsule"  />
                    <geom size="0.04 0.07" pos="-0.1 0.1 0" quat="0.707388 0 0.706825 0" type="capsule"  />
                    <body name="latch_axis" pos="0 -0.15 0" quat="0.7071 0.7071 0 0">
                        <geom size="0.01" pos="0. 0. 0." quat="1 0 0 0" type="sphere" contype="0" conaffinity="0" rgba="1 1 1 1" />
                    </body>
            </body>
          </body>
      </body> -->


    </body>
    <site name="bottom_site" pos="0 0 -0.3" rgba="0 0 0 0" size="0.005"/>
    <site name="top_site" pos="0 0 0.3" rgba="0 0 0 0" size="0.005"/>
    <site name="horizontal_radius_site" pos="0.3 0 0" rgba="0 0 0 0" size="0.1"/>
  
</mujocoinclude>


